Workbook
Name bd: #REF!

Sheet Check-List
C2: Check List de Auditoria ISO 13485:2016
B4: INFORMAÇÕES GERAIS
B5: Unidade | C5: Visolab | I5: Tipo de Auditoria
B6: Nome do Auditor: | C6: Vinicius Mota | J6: Remota
B7: Data de Auditoria: | C7: 20/05/2026 a 22/07/2026 | I7: X | J7: Presencial
B8: Escopo | C8: Laboratório de Montagem e Distribuição de Lentes Oftálmicas
B9: Plano de Ação (caso tenha alguma NC ou OM)
B10: *Legenda
B11: C: Conforme NC: Não Conforme NA: Não Aplicável OM: Oportunidade de Melhoria
B12: Item | C12: Questão | D12: C | E12: NC | F12: NA | G12: OM | H12: Evidência | I12: Observação
B13: SISTEMA DE GESTÃO DA QUALIDADE | K13: =COUNTIF(D14:D24,"X") | L13: =COUNTIF(E14:E24,"X") | M13: =COUNTIF(G14:G24,"X")
B14: 4.1.1 | C14: A organização documenta seu papel em relação aos requisitos regulatórios aplicáveis? | D14: X | H14: • [Conforme] Manual de compras: DOC.085.R0 Manual de Compras - Visolab • [Conforme] Procedimento para recebimento de lentes e bloco: POP.1122.R0: Manual Operacional - Recebimento de Lentes e Blocos - Visolab • [Conforme] Gestão de Riscos: PSQ.028.R5: Gestão de Risco | K14: =(K13)/(K13+L13+M13) | L14: =(L13)/(K13+L13+M13) | M14: =(M13)/(K13+L13+M13)
B15: 4.1.2 | C15: A organização possui uma estrutura de: - Hierárquica dos documentos; - Controle dos riscos dos processos; - Sequência e intereção dos processos. | D15: X | H15: • [Conforme] MAQ.002.R10 - Manual da Qualidade: - Organograma - Gestão de Risco - Interação de Processos - Tabela de Competência e Responsabilidade • [Conforme] Matriz de Risco do SGQ e Processos: FOR.061: Matriz de Risco Geral
B16: 4.1.3 | C16: A organização controla a documentação da qualidade? Assegura que a documentação de suporte necessária esteja disponível? | D16: X | H16: • [Conforme] Matriz de Risco do SGQ e Processos: FOR.061: Matriz de Risco Geral
B17: 4.1.4 | C17: As mudanças realizadas na documentação são avaliadas com relação ao seu impacto no SGQ e produtos? | D17: X | H17: • [Conforme] PSQ.029.R3: Gestão de Mudança: FOR.071: Solicitação de Mudança - SM
B18: 4.1.5 | C18: A organização terceiriza algum processo? Monitora e assegura os controles dos processos? | D18: X | H18: • [Conforme] PSQ.018.R2: Realização de Produto: FOR.146: Lista de Fornecedores Qualificados • [Conforme] PSQ.018.R2: Realização de Produto: FOR.147: Avaliação e Reavaliação de Fornecedores
B19: 4.1.6 | C19: A organização documentou procedimento de validação de softwares que impactem no SGQ? | D19: X | H19: • [Conforme] PSQ.027.R2: Validação: FOR.166: Validação de Software: Validação do Sistema Sysprola
B20: 4.2.1 | C20: A organização documentou a Política da Qualidade? | D20: X | H20: • [Conforme] MAQ.002.R10 - Manual da Qualidade: - Política da Qualidade
B21: 4.2.2 | C21: A organização documentou o Manual da Qualidade? | D21: X | H21: • [Conforme] MAQ.002.R10 - Manual da Qualidade: - Escopo do SGQ - Estrutura Organizacional - Interação de Processos
B22: 4.2.3 | C22: A organização possui documentação dos produtos? (Descrição, especificações, registro, procedimentos relacionados ao produto?) | D22: X | H22: • [Conforme] POP.1002.R1 - Manual Operacional - Rastreabilidade de Pedidos Visolab • [Conforme] DMR: DOC.085.R0 Manual de Compras - Visolab; POP.1057.R0 Manual Operacional - Comunicação com o Cliente - Visolab
B23: 4.2.4 | C23: A organização documentou procedimento para controlar, analisar, aprovar, previnir deterioração, previnir uso não intencional e assegurar que as versões vigentes dos documentos estejam disponíveis? | D23: X | H23: • [Conforme] PSQ.017.R3 - Controle de Documentos e Registros
B24: 4.2.5 | C24: A organização documentou procedimento para definir, identificar, armazenar, dar tempo de retenção, garantir a integridade e rápida recuperação de registros? | D24: X | H24: • [Conforme] PSQ.017.R3 - Controle de Documentos e Registros
B25: RESPONSABILIDADE DA DIREÇÃO | K25: =COUNTIF(D26:D36,"X") | L25: =COUNTIF(E26:E36,"X") | M25: =COUNTIF(G26:G36,"X")
B26: 5.1 | C26: A alta direção fornece evidência de seu comprometimento com os requisitos do SGQ: política da qualidade, objetivos da qualidade e conduz análises críticas? | D26: X | H26: • [Conforme] MAQ.002.R10 - Manual da Qualidade: - Política da Qualidade - Objetivos da Qualidade - Avaliação de Riscos | K26: =(K25)/(K25+L25+M25) | L26: =(L25)/(K25+L25+M25) | M26: =(M25)/(K25+L25+M25)
B27: 5.2 | C27: A alta direção assegura que os requisitos regulatórios e aplicáveis sejam determinados e atendidos? | D27: X | H27: • [Conforme] MAQ.002.R10 - Manual da Qualidade: - Foco no Cliente
B28: 5.3 | C28: A alta direção assegura que a política da qualidade seja aplicável, seja comunicada e compreendida e a analisa criticamente para sua contínua adequação? | D28: X | H28: • [Conforme] MAQ.002.R10 - Manual da Qualidade: - Política da Qualidade
B29: 5.4.1 | C29: A alta direção assegura que os objetivos da qualidade, sejam estabelecidos em funções e níveis relevantes dentro da organização? Os objetivos da qualidade são mensuráveis e coerentes com a política da qualidade? | D29: X | H29: • [Conforme] MAQ.002.R10 - Manual da Qualidade: - Objetivos da Qualidade
B30: 5.4.2 | C30: A alta direção assegura que o planejamento do sistema de gestão da qualidade seja realizado de forma a satisfazer os requisitos fornecidos em 4.1, assim como os objetivos da qualidade? A integridade do sistema de gestão da qualidade é mantida quando alterações no sistema de gestão da qualidade forem planejadas e implementadas? | D30: X | H30: • [Conforme] MAQ.002.R10 - Manual da Qualidade: - Planejamento do SGQ - Gestão de Mudança
B31: 5.5.1 | C31: A alta direção documenta e assegura a inter-relação do pessoal que gerencia, desempenha e verifica o trabalho? | D31: X | H31: • [Conforme] MAQ.002.R10 - Manual da Qualidade: - Organograma e Responsabilidades
B32: 5.5.2 | C32: A organização possui um representante da direção indicado pela alta direção? | D32: X | H32: • [Conforme] Nomeação do RD: FOR.118: Nomeação RD
B33: 5.5.3 | C33: A alta direção assegura um processo de comunicação apropriado à organização com relação ao SGQ? | D33: X | H33: • [Conforme] MAQ.002.R10 - Manual da Qualidade: Comunicação Interna
B34: 5.6.1 | C34: A organização documentou procedimento para análise crítica pela direção? | D34: X | H34: • [Conforme] PSQ.025.R1: Revisão Gerencial: FOR.069: Ata de Reunião de Análise Crítica pela Direção
B35: 5.6.2 | C35: As entradas são criticamente analisadas pela direção? (Feedback, tratamento de reclamações, comunicação às autoridades regulatórias, auditorias, monitoramento e medição de processos, monitoramento e medição de produtos, ação corretiva, ação preventiva, ações provenientes de análises anteriores, alterações que impactem o SGQ, recomendações de melhorias e requisitos regulatórios aplicáveis) | D35: X | H35: • [Conforme] PSQ.025.R1: Revisão Gerencial: FOR.069: Ata de Reunião de Análise Crítica pela Direção
B36: 5.6.3 | C36: As saídas de análise crítica são registradas? (Melhorias necessárias para adequação e eficácia do SGQ, melhorias de produto, alterações para atender requisitos regulatórios, recursos) | D36: X | H36: • [Conforme] PSQ.025.R1: Revisão Gerencial: FOR.069: Ata de Reunião de Análise Crítica pela Direção
B37: GESTÃO DE RECURSOS | K37: =COUNTIF(D38:D42,"X") | L37: =COUNTIF(E38:E42,"X") | M37: =COUNTIF(G38:G42,"X")
B38: 6.1 | C38: A organização determina e provê os recursos para implementação e atendimento à requisitos regulatórios e de clientes do SGQ? | D38: X | H38: • [Conforme] MAQ.002.R10 - Manual da Qualidade: Recursos e Infraestrutura | K38: =(K37)/(K37+L37+M37) | L38: =(L37)/(K37+L37+M37) | M38: =(M37)/(K37+L37+M37)
B39: 6.2 | C39: O pessoal que executa o trabalho que afeta a qualidade possui competência e é treinado para a atividade que exerce? Os registros são mantidos? A eficácia é avaliada? | D39: X | H39: • [Conforme] PSQ.023.R4: Treinamentos: Matriz de Treinamento, Descrição de Cargos, Avaliação de Eficácia
B40: 6.3 | C40: A organização documenta os requisitos para a infraestrutura necessária para alcançar a conformidade com requisitos do produto? Previne mistura de produtos?A organização documenta os requisitos para a atividade de manutenção? Incluindo intervalo de execução, quando as atividades ou falta delas afetarem os produtos. | D40: X | H40: • [Conforme] PSQ.033.R2: Manutenção: Plano de Manutenção Preventiva de Equipamentos
B41: 6.4.1 | C41: A organização documenta os requisitos do ambiente necessário para alcançar a conformidade com os produtos incluindo requisitos de saúde, limpeza e vestuário do pessoal que afete a qualidade do produto? O pessoal requisitado temporariamente possui competência para tal e/ou é supervisionado para tal? | D41: X | H41: • [Conforme] POP.1005.R1: Manual Operacional - Limpeza e Higienização do Laboratório
B42: 6.4.2 | C42: A organização planeja e documenta as tratativas para controle de produtos contaminados ou potencialmente contaminados para previnir contaminação do ambiente de trabalho, pessoal e produtos? | D42: X | H42: • [Conforme] POP.1005.R1: Manual Operacional - Limpeza e Higienização do Laboratório
...

Sheet Evidências
B3: EVIDÊNCIAS COM IMAGENS

Sheet Resultados
B2: ITENS DA ISO 13485 - 2016 | N2: Percentual auditado | O2: =(E9+F9+H9)/D9
B3: Seções | C3: Total | D3: Auditados | E3: C | F3: NC | G3: NA | H3: OM | I3: Conforme | J3: Não Conforme | K3: Oportunidade de Melhoria | L3: Meta | N3: Resultado geral | O3: =(E9+H9)/(D9)
B4: 4 Sistema de Gestão da Qualidade | C4: =COUNTA('Check-List'!B14:B24) | D4: =C4-G4 | E4: =COUNTIF('Check-List'!D14:D24,"x") | F4: =COUNTIF('Check-List'!E14:E24,"x") | G4: =COUNTIF('Check-List'!F14:F24,"x") | H4: =COUNTIF('Check-List'!G14:G24,"x") | I4: =E4/D4 | J4: =F4/D4 | K4: =H4/D4 | L4: 1
B5: 5 Responsabilidade da Direção | C5: =COUNTA('Check-List'!B26:B36) | D5: =C5-G5 | E5: =COUNTIF('Check-List'!D26:D36,"x") | F5: =COUNTIF('Check-List'!E26:E36,"x") | G5: =COUNTIF('Check-List'!F26:F36,"x") | H5: =COUNTIF('Check-List'!G26:G36,"x") | I5: =E5/D5 | J5: =F5/D5 | K5: =H5/D5 | L5: 1
B6: 6 Gestão de Recursos | C6: =COUNTA('Check-List'!B38:B42) | D6: =C6-G6 | E6: =COUNTIF('Check-List'!D38:D42,"x") | F6: =COUNTIF('Check-List'!E38:E42,"x") | G6: =COUNTIF('Check-List'!F38:F42,"x") | H6: =COUNTIF('Check-List'!G38:G42,"x") | I6: =E6/D6 | J6: =F6/D6 | K6: =H6/D6 | L6: 1
B7: 7 Realização do Produto (Fabricação) | C7: =COUNTA('Check-List'!B44:B73) | D7: =C7-G7 | E7: =COUNTIF('Check-List'!D44:D73,"x") | F7: =COUNTIF('Check-List'!E44:E73,"x") | G7: =COUNTIF('Check-List'!F44:F73,"x") | H7: =COUNTIF('Check-List'!G44:G73,"x") | I7: =E7/D7 | J7: =F7/D7 | K7: =H7/D7 | L7: 1
B8: 8 Medição, Análise e Melhoria | C8: =COUNTA('Check-List'!B75:B89) | D8: =C8-G8 | E8: =COUNTIF('Check-List'!D75:D89,"x") | F8: =COUNTIF('Check-List'!E75:E89,"x") | G8: =COUNTIF('Check-List'!F75:F89,"x") | H8: =COUNTIF('Check-List'!G75:G89,"x") | I8: =E8/D8 | J8: =F8/D8 | K8: =H8/D8 | L8: 1
B9: Total | C9: =SUM(C4:C8) | D9: =SUM(D4:D8) | E9: =SUM(E4:E8) | F9: =SUM(F4:F8) | G9: =SUM(G4:G8) | H9: =SUM(H4:H8) | I9: =E9/D9 | J9: =F9/D9 | K9: =H9/D9 | L9: 1
B13: Percentual de Atendimento a ISO 13485 - 2016
B43: Seções | C43: NC | D43: OM | E43: Principais itens
B44: 4 Sistema de Gestão da Qualidade | C44: =F4 | D44: =H4
B45: 5 Responsabilidade da Direção | C45: =F5 | D45: =H5
B46: 6 Gestão de Recursos | C46: =F6 | D46: =H6
B47: 7 Realização do Produto (Fabricação) | C47: =F7 | D47: =H7
B48: 8 Medição, Análise e Melhoria | C48: =F8 | D48: =H8
C49: =SUM(C44:C48) | D49: =SUM(D44:D48)

Sheet atenção
C2: Item | D2: Questão | E2: C | F2: NC | G2: NA | H2: OM | I2: Evidência | J2: Observação
B3: SISTEMA DE GESTÃO DA QUALIDADE | C3: 4.1.6 | D3: A organização documentou procedimento de validação de softwares que impactem no SGQ? | F3: X | I3: - PSQ.029 - Procedimento de Gestão de Mudança - FOR.137 - Relatório de Gestão de Mudança (Software utilizados desde o início do laboratório, garantindo sua eficiência e rastreabilidade. Caso ocorra alguma mudança, será validado no FOR.137) | J3: Corporativo: Atualizar PSQ.027 - Procedimento de Validação. Criar formulários de validação de software. Corporativo + Rio: Preencher formulários de validação dos softwares (DECIDE, SMR, SGO, Optifacts e Qualiex).
B4: RESPONSABILIDADE DA DIREÇÃO | C4: 5.1 | D4: A alta direção fornece evidência de seu comprometimento com os requisitos do SGQ: política da qualidade, objetivos da qualidade e conduz análises críticas? | H4: x | I4: Reuniões com diretoria, alinhamento da ata e atuação em pesquisa de satisfação | J4: Realizar uma nova Revisão Gerencial, incluindo principalmente as saídas em relação a pesquisa de satisfação. Verificar também itens em relação a indicadores / BSC (Aluysio) - (ação em conjunto com item 5.6.3, 6.3 e 8.1) Verificar atalho no drive sobre a pesquisa de satisfação e suas tratativas. | L4: =(#REF!)/(#REF!+#REF!+#REF!) | M4: =(#REF!)/(#REF!+#REF!+#REF!) | N4: =(#REF!)/(#REF!+#REF!+#REF!)
C5: 5.2 | D5: A alta direção assegura que os requisitos regulatórios e aplicáveis sejam determinados e atendidos? | H5: x | I5: Saúde visual: Decide, UV, SMR (verificação da luz azul...) | J5: Não temos algumas normas sendo seguidas na integra, mas temos algumas especificações dos produtos controlados no qualiex. A não utilização da ISO para tolerancia otica será levada para os coordenadores de QMS
C6: 5.5.1 | D6: A alta direção documenta e assegura a inter-relação do pessoal que gerencia, desempenha e verifica o trabalho? | H6: x | I6: - Descrição de Atividade (https://apps1.qualiex.com/Docs/Documents?folder=F2EQJCC4VTK9EUF) - FOR.109 - Matriz de Habilidade - LabRio 2022 - Rev.02 (https://docs.google.com/spreadsheets/d/1T_WW9coCXAHY78KyFNexxG3kZl0v6NlrttpXbVh2Whk/edit#gid=217238903) | J6: Não está existe documento no Qualiex em relação a Descrição de Atividade para os seguintes setores: - Atendimento ao cliente; - Estoque; - Expedição; - Recursos Humanos; - EHS.
C7: 5.5.3 | D7: A alta direção assegura um processo de comunicação apropriado à organização com relação ao SGQ? | H7: x | I7: - Será retornado as reuninões sobre comunicações relativas à eficiência do sistema de gestão da qualidade. | J7: Planejar e executar as reuniões periódicas em relação a comunicação do SGQ.
C8: 5.6.3 | D8: As saídas de análise crítica são registradas? (Melhorias necessárias para adequação e eficácia do SGQ, melhorias de produto, alterações para atender requisitos regulatórios, recursos) | H8: x | I8: - PSQ.025 - Procedimento de Revisão da Gestão - FOR.135 - Relatório de Revisão Gerencial (https://docs.google.com/spreadsheets/d/1Gub8MKyYp5AcNQUssAbOZvvp_giuviFk/edit#gid=993094433) | J8: - Verificar pesquisa de satisfação do cliente; - Realizar um reunião para gerar revisão gerencial (ação em conjunto com item 5.1 e 6.3)
B9: GESTÃO DE RECURSOS | C9: 6.2 | D9: O pessoal que executa o trabalho que afeta a qualidade possui competência e é treinado para a atividade que exerce? Os registros são mantidos? A eficácia é avaliada? | H9: x | I9: - FOR.109 - Matriz de Habilidade; - FOR.133 - Planejamento de Treinamento; - RH.FOR.033 - Lista de Presença; - FOR.092 - Controle de Treinamento; - FOR.141 - Auto Avaliação; - FOR.142 - Avaliação de Eficácia do Treinamento. https://drive.google.com/drive/u/2/folders/1sfWNKRbX0vut3uYUaA1AGx5ozfhCHxM8 - Comunicação para todos os colaboradores via e-mail sobre os treinamentos realizados. | J9: - RH precisa melhorar o preenchimento, avaliação - Líderes: Preenchimento da matriz de habilidade e planejamento de treinamento
C10: 44626 | D10: A organização documenta os requisitos para a infraestrutura necessária para alcançar a conformidade com requisitos do produto? Previne mistura de produtos?A organização documenta os requisitos para a atividade de manutenção? Incluindo intervalo de execução, quando as atividades ou falta delas afetarem os produtos. | F10: x | I10: ver se existe tratativa para temperatura e umidade fora da especificação https://docs.google.com/spreadsheets/d/13-t8DcNUfXAYLzoNum8xvjTCJoprYP4Zy8TV3HzyoKg/edit#gid=1473838937 **ver na aba evidências | J10: Relatório para verificação das particulas da sala limpa não traz informações suficientes para comparar com o padrão. Será abordado na nova revisão gerencial para tomar novas ações para validação https://apps1.qualiex.com/Docs/Documents/Details/ADC2DLVPAE0D2JN Temperatura da sala fora de especificação. Qual é a tratativa neste ponto? https://docs.google.com/spreadsheets/d/13-t8DcNUfXAYLzoNum8xvjTCJoprYP4Zy8TV3HzyoKg/edit#gid=1473838937
B11: REALIZAÇÃO DE PRODUTO (FABRICAÇÃO) | C11: 7.1 | D11: A organização planeja e desenvolve processos necessários para a realização do produto? A organização documenta processos para o gerenciamento de risco? O planejamento da realização do produto inclui os objetivos da qualidade, necessidade de estabelecer processos e documentos, atividades requeridas de verificação, validação, monitoramento, inspeção e ensaio, manuseio, armazenamento, distrubuição e rastreabilidade específicas para o produto? Os registros são armazenados? | F11: x | I11: - FOR.081 - Formulário HMC - PCP Latam Português - Lab Geral - LabRio 2022 Rev.01 (https://docs.google.com/spreadsheets/d/13-t8DcNUfXAYLzoNum8xvjTCJoprYP4Zy8TV3HzyoKg/edit#gid=2131303326) | J11: - Valores precisam ficar no formato padrão, para não gerar não conformidades; - Ações para especificações fora. | L11: =(L10)/(L10+M10+N10) | M11: =(M10)/(L10+M10+N10) | N11: =(N10)/(L10+M10+N10)
C12: 7.2.3 | D12: A organização planeja e documenta os arranjos de comunicação com o cliente em relação a informações do produto, tratamento de solicitações, contratos ou pedidos, feedbacks dos clientes, notas de aviso? Os registros são armazenados? | H12: x | I12: - Ponta comercial (pós-venda e televendas): realizado comunicação com o cliente (ótica) - LabRio: Comunicação é feita com a ponta comercial, ponta comercial entra em contato com a ótica. Dependendo do caso setor técnico (Equipe do Rogério Castro) entrar em contato ótica. | J12: - Precisa criar procedimentos em relação a comunicação com o cliente, contendo: b)tratamento de solicitações, contratos ou pedidos, incluindo emendas; c)realimentação do cliente, incluindo reclamações; d)notas de aviso. - Juntar com o item 8.2.2
C13: 7.5.1 | D13: Caso a organização forneça um serviço, este é planejado, monitorado e controlado para que se assegure conformidade com especificações? Existe procedimentos documentados para isso? Os registros são armazenados devidamente? | F13: x | I13: verificar um pedido no sistema e solicitar o rastreamento em questão planejamento de produção, verificação de Decide, SMR lote salvo + preenchimento da planilha - verificar registro FOR.132: Controle de Utilização do UV 400 | J13: - Faltou folheto (em evidências), conforme documento TAB.009 - Tabela de Embalagens nas Linhas Digitais - Lente colorida organica não segue o procedimento de UV, porém é aplicado Spin antes e depois colocar 1 minuto no UV. (atualizar no procedimento) - Finalizar procedimento de rastreabilidade de pedido (Deyved) - Realizar procedimento de rastreamento do DECIDE (Renan)
C14: 7.5.6 | D14: A organização possui procedimento para validação de qualquer processo de produção e fornecimento como software e outras ferramentas que sejam necessárias? O procedimento possui critérios de avaliação, qualificação de equipamentos e pessoal, técnicas estatísticas, requisitos de registros, etc.? | F14: x | I14: ver validação de software ver calibração do SMR e treinamento em relação a calibração PSQ.027 - Procedimento de Validação FOR.159 - Validação de Softaware | J14: - Validar os software - Compra das lentes de referências do SMR para calibração
C15: 7.5.8 | D15: A organização documenta procedimento para identificação dos produtos em todas as etapas de produção e distribuição? Os produtos em situação de quarentena e não conforme são identificados impossibilitando seu uso intensional? | H15: x | I15: - POP.734 - Manual Operacional - Produto Não Conforme - Lab Rio | J15: - Identificar novamente alguns setores, pois está com identificação falhada.
C16: 7.5.9.1 | D16: A organização documenta procedimento de rastreabilidade dos produtos? | H16: x | I16: - PSQ.026 - Procedimento de Identificação e Rastreabilidade | J16: Melhorar a forma de rastrear o bloco de origem, pois a informação do lote do bloco fica até a surfaçagem
C17: 7.5.10 | D17: A organização identifica, verifica, protege e resguarda itens de propriedade do cliente como contratos, documentos e registros?Isso é comunicado ao cliente? | H17: x | I17: - PSQ.019 - Procedimento de Preservação de Insumo e Produto | J17: - Comunicação entre LabRio e cliente é realizado via: telefone ou e-mail, não conseguiu mostrar um recente. - Revisar POP.744 com informação de identificação de rastreabilidade.
C18: 7.5.11 | D18: A organização documenta procedimento para preservação do produto durante as etapas de processamento, armazenamento, manuseio e distribuição? Alem das condições de acondicionamento, há proteção na identificação dos produtos? | F18: x | I18: - FOR.122 - Controle de Umidade e Temperatura: Estoque (https://docs.google.com/spreadsheets/d/1kjU-wzLLU-qzkQ3GL8zqVIIeupvNDeT4H8XEIilT8lg/edit#gid=375603829) - FOR.155 - Controle de Temperatura de Armazenamento: Primers e Vernizes (https://docs.google.com/spreadsheets/d/1Q_hgaDNwmnIH2fVKgHvXqD-KV-kwtULi4ELrETe89ek/edit#gid=375603829) - FOR.006 - Inspeção e Testes de Recebimento de Insumos (https://docs.google.com/spreadsheets/d/17tXRyq55mFrfbAMjr0A9TO2ONTMswttK6Ac1xJh2F-s/edit#gid=309398118) | J18: - Realizar tratativa para adequar a temperatura do estoque e também para as medições do turno 3; - Realizar preenchimento e controle da temperatura dos vernizes (FOR.155) (falaram que existe preenchimento em papel) - Verificar os galões de vernizes do estoque para confirmar se estão todos etiquetados; - Faltam certificados dos vernizes recebidos em 2021
C19: 7.6 | D19: A organização determina o monitoramento e a medição nos equipamentos de monitoramento e medição dos produtos? Há uma verificação sistemática e periódica? Os registros são devidamente armazenados? Os equipamentos são identificados? Os equipamentos são protegidos contra danos, deterioração durante manuseio, manutenção e armazenamento? | F19: x | I19: https://drive.google.com/drive/u/2/folders/1OD08q5FfBaChxQSvgQ6eYJr1EW-ADfX3 | J19: - Stephany: Garantir a gestão completa dos equipamentos que garantem testes e inspeção
B20: MEDIÇÃO, ANÁLISE E MELHORIA | C20: 8.1 | D20: A organização planeja e implementa processos de monitoramento, medição, análise e melhoria que demonstrem e assegurem a eficácia dos produtos e SGQ? | H20: x | I20: - PSQ.025 - Procedimento de Revisão da Gestão | J20: Verifica Relatorio da revisão gerencial que está no item "Melhoria" como "Não se aplica" | L20: =(#REF!)/(#REF!+#REF!+#REF!) | M20: =(#REF!)/(#REF!+#REF!+#REF!) | N20: =(#REF!)/(#REF!+#REF!+#REF!)
C21: 8.2.1 | D21: A organização documenta procedimento para realimentação (feedback, sugestões, reclamações, dúvidas)? Determina e monitora informações de atendimento as especificações dos clientes? | H21: x | I21: - POP.747 - Monitoramento de Realimentação do Cliente | J21: ver com atendimento Não possui evidência das tratativas
C22: 8.2.2 | D22: A organização documenta procedimento para tratamento de reclamações? O tempo de resposta atende às especificações dos clientes e requisitos regulatórios? Documenta procedimento para ações corretivas e preventivas provenientes de investigações de reclamações? | H22: x | I22: - Reclamações de qualidade do produto é realizado pelo departamento técnico (Rogério Castro); - Via e-mail; - Orgaplus é possível gerar relatórios de reclamação por produto (criar procedimento como é feito este relatório). | J22: - Fazer procedimento com os tratamentos das reclamações, contendo: a)receber e registrar as informações; b)avaliar as informações de modo a determinar se a realimentação constitui reclamação; c)investigar reclamações; d)determinar a necessidade de comunicar as informações às autoridades regulatórias apropriadas; e)tratar reclamações relacionadas ao produto; f)determinar a necessidade de iniciar correções ou ações corretivas. - Pode ser realizado junto com o item 7.2.3
C23: 8.2.4 | D23: A organização possui procedimento para auditoria interna? As autoridades são definidas? Os registros são mantidos? É realizado acompanhamento de atividades apontadas em outras auditorias? | H23: x | I23: - PSQ.024 - Procedimento de Auditoria - Auditoria de QMS (Interna, externa e terceiros) Ok - Auditoria 5S (https://drive.google.com/drive/u/2/folders/11lCPkGxau8Ibz4N8EvDQem211uUc5mV_) - Auditoria de Produto (https://drive.google.com/drive/u/2/folders/1j3rBXGSNhi0g3KsW5KMMhMjVlb_Izy2r) | J23: - Corporativo: Retirar auditoria de excelência operacional do PSQ 024 e obsoletar o formulario de excelencia operacional - LabRio: realizar tratativas dos resultados das auditorias
C24: 8.2.5 | D24: É realizado monitoramento e medição dos processos do SGQ? Possui KPIs? Os resultados planejados que não forem alcançados, são realizadas correções e ações corretivas? | F24: x | I24: BSC fora da meta: - Retorno de cliente: Janeiro - Service Rate: Fevereiro e maio - Late orders: Fevereiro, março abril e maio | J24: Realizar tratativa com plano de ação no mínimo
C25: 8.2.6 | D25: A organização monitora características e requisitos do produto? É realizado registro dos responsáveis por liberação do produto para fim de rastreabilidade? | F25: x | I25: - PSQ.018 - Procedimento de Realização de Produto; - FOR.116 - Formulario de Testes HC e AR (https://docs.google.com/spreadsheets/d/1MRF52Nt2TblCMqKqboUWAnb5kBrdbm05JKBBuQ2TMDE/edit#gid=219170642) | J25: Não está sendo indetificado quem libera lote em testes do AR
C26: 8.3.3 | D26: A organização adota ações apropriadas aos efeitos ou efeitos potencias do produto não conforme após a entrega ou início do uso? Possui procedimentos para a emissão de notas de aviso? Os registros são mantidos? | F26: x | I26: - POP.747 - Monitoramento de Realimentação do Cliente | J26: - Criar procedimento de como é realizado o recolhimento do produto;
C27: 8.4 | D27: A organização documenta procedimento para determinar coleta e análise de dados referente a reclamações, feedbacks, requisitos regulatórios, fornecedores, auditorias, relatórios de serviços e tratá-los? | F27: x | I27: - PSQ.025 - Procedimento de Revisão da Gestão | J27: - Registro pela chamada (solicitação via telefone) - Precal (identificação via relatório fisico) - Tratativas: Conversa, treinamento (sem registro)
C28: 8.5.1 | D28: A organização identifica e implementa ações para assegurar melhoria contínua do SGQ e outros processos relacionados ao produto? | H28: x | J28: - Retomar as auditorias de 5S - última realizada em 22 abril - Gerar plano de ação para as tratativas das auditorias de produto
C29: 8.5.2 | D29: A organização possui procedimento para ações corretivas que aborde a análise das não conformidades, avalia a necessidade de ações para que elas não recorram, necessidade de atualização de documentação e analise eficácia da ação adotada? | H29: x | I29: - PSQ.022 - Procedimento de Não Conformidade-Ações Corretivas e Preventivas | J29: - Relacionamento com o cliente: possui conversa e treinamento, mas não possui registros para evidências. (Itens relacionados:7.2.3, 8.2.2 e 8.5.2)
C30: 8.5.3 | D30: A organização determina ações para eliminar causas de não conformidades potênciais? Possui procedimento para para determinação de não conformidades potenciais, avalia a necessidade de ações para prevenir novas não conformidades, planeja e documenta ações necessárias e as implementa conforme apropriado? | H30: x | I30: - PSQ.022 - Procedimento de Não Conformidade-Ações Corretivas e Preventivas | J30: - Gerar evidências para as tratativas de RNC, 8D e A3. (incluso no plano junto ao item 7.1)
E31: =COUNTIF(E3:E30,"X") | F31: =COUNTIF(F3:F30,"X") | G31: =COUNTIF(G3:G30,"X") | H31: =COUNTIF(H3:H30,"X")
