Workbook

Sheet Orientações
B2: Orientações para utilização do Relatório de Gestão de Mudança
C4: O setor de origem da necessidade de mudança deve gerenciar a abertura e acompanhamento do Formulário Gestão de Mudança.
B5: Passos a serem seguidos:
C6: 1) Criar uma cópia deste formulário
C7: 2) Entender o escopo da mudança e chamar os principais envolvidos para abertura do relatório. Qualidade e EHS são áreas que participam, obrigatoriamente, deste processo inicial.
C8: 3) Iniciar as descrições iniciais da mudança
C9: 3.1) o Nº do Registro deve ser verificado e criado junto ao controle de Solução de Problema da unidade, para garantir a sequencia dos formulários
C10: 4) O técnico de segurança da unidade e, para unidades que não possui técnico de segurança, um membro do EHS Corporativo, é o profissional responsável pela análise dos questionamentos e preenchimento das abas do Pilares de EHS Pilares de EHS: PESSOAS, MEIO AMBIENTE, PROPRIEDADE E CONFORMIDADE
C11: 4.1) Para cada "N" (não) selecionado nos itens dos Check list dos Pilares de EHS, é necessário gerar ações para atendimento a referência pontuada
C12: 4.2) A seção de "Impactos ambientais", trazem de forma automática o indicador desta Gestão de Mudança, a partir do preenchimento das abas relevantes (Pilares EHS)
C13: 4.3) Em casos de preenchimento das abas dos Pilares de EHS, a seção de "Análise Crítica pelas áreas avaliadoras", precisa ser preenchida e assinada pelo Responsável da Mudança, e pelo Técnico de segurança da unidade e, para unidades que não possui técnico de segurança, um membro do EHS Corporativo
C14: 4.4) Certas ações podem ser designadas pelo EHS antes da implementação da mudança.
C15: 4.5) Em casos de preenchimento das abas dos Pilares de EHS a revisão final Relatório de Gestão de Mudança será realizado também pelo Técnico de segurança da unidade e, para unidades que não possui técnico de segurança, um membro do EHS Corporativo, para garantir que todos os itens do Plano de Ação foram concluídos.
C16: 5) O controle deste registro deverá seguir o PSQ.017: Controle de Documentos e Registros
C17: 6) Atualizar informações deste relatório no FOR.164 - Controle Anual dos Registros

Sheet Relatório de Gestão de Mudança
C2: Relatório de Gestão de Mudança | G2: FOR.137.R5
B4: INFORMAÇÕES GERAIS
B5: Unidade: | F5: Data da abertura:
B6: Solicitante: | F6: Nº do Registro:
B7: Tipo de mudança: | C7: ( ) Regulatório ( ) QMS/SGI ( ) Projetos ( ) Produto ( ) Software ( ) Processo ( ) Equipamento ( ) Organizacional ( ) Layout ( ) Insumo ( ) Outros:__________________________________
B8: Prioridade de mudança: | C8: ( ) Urgente ( ) Alto ( ) Médio ( ) Baixo
B9: Área (s) impactada (s)
B10: Área avaliadora: (setores / departamentos)
B12: DADOS DA MUDANÇA
B13: Situação (Antes da Mudança):
B14: Situação Projetada (Após Mudança):
B15: Justificativa:
B16: Benefícios:
B17: Data da Mudança / Projeto:
B18: EVIDÊNCIA: (imagens e/ou informações antes da mudança)
B20: IMPACTOS DE EHS
B21: Para avaliar em detalhes todos os impactos de EHS para a mudança, verifique todos os tópicos que se aplicam => veja as opções abaixo.
B22: Imput | C22: Pilares de EHS | G22: Referência Necessária
G23: Somatório | H23: %
B24: Pessoas: | C24: Saúde, segurança química, elétrica, organizacional e ergonomia. | G24: =SUM('H & S'!F37+Chemical!F28+Eletrical!F29+Organizational!F29+Ergonomics!F70) -> 0 | H24: =IFERROR(G24/('H & S'!H37+Chemical!H28+Eletrical!H29+Environment!H27+Organizational!H29+Ergonomics!H70+Equipament!H34+Facilities!H29+'Emergency & Fire'!H27+Compliance!H12),"-") -> -
B25: Meio Ambiente: | C25: Emissões atmosféricas, produtos químicos, consumo de energia e água, geração e descarte de resíduos e emissões de efluentes. | G25: =Environment!F27 -> 0 | H25: =Environment!F28 -> -
B26: Propriedades e ativos: | C26: Instalações, equipamentos, preparação para emergências e prevenção/proteção contra incêndios e explosões. | G26: =SUM(Equipament!F34+Facilities!F29+'Emergency & Fire'!F27) -> 0 | H26: =IFERROR(G26/(Equipament!H34+Facilities!H29+'Emergency & Fire'!H27),"-") -> -
B27: Compliance: | C27: Permissões locais ou regulamentos aplicáveis. | G27: =Compliance!F12 -> 0 | H27: =Compliance!F13 -> -
B29: RISCOS ENVOLVIDOS: (segurança, paralisação de atividades, meio ambiente, software etc.)
B30: Quais processos serão afetados pela mudança:
B31: Quais módulos do sistema serão afetados:
B32: Como a mudança afeta o processo atual:
B33: Consequência de não realizar a mudança:
B34: Riscos identificados:
B35: Tratamento dos riscos:
B36: Plano de contingência em caso de riscos:
B37: Áreas envolvidas na implantação:
B38: Observações:
B39: Gerar plano de ação: | C39: Vide aba: Plano de Ação | F39: Percentual de conclusão do plano: | H39: ='Plano de ação'!J5 -> -
B41: ÁNALISE CRÍTICA PELAS ÁREAS AVALIADORAS
B42: Mudança será implantada: | C42: ( ) Sim ( ) Não
B43: Justificativa / parecer:
B44: Responsável pela decisão: | F44: Data:
B45: Justificativa / parecer:
B46: Responsável pela decisão: | F46: Data:
...

Sheet Plano de ação
E2: PLANO DE AÇÃO | PLAN DE ACCIÓN
B3: Laboratório, Área ou Projeto: Nombre de proyecto, area o Lab: | E3: ='Relatório de Gestão de Mudança'!C5 -> 0 | G3: ="AÇÕES PLANEJADAS (ACCIONES PLANEADAS): "&COUNTIF(J9:J208,"Planeada/Planejada") -> AÇÕES PLANEJADAS (ACCIONES PLANEADAS): 0 | J3: Percentual de Conclusão:
G4: ="AÇÕES COMPLETAS (ACCIONES COMPLETAS): "&COUNTIFS(J9:J208,"Completa/Concluído") -> AÇÕES COMPLETAS (ACCIONES COMPLETAS): 0
B5: Nº Registro: | E5: ='Relatório de Gestão de Mudança'!G6 -> 0 | G5: ="AÇÕES EM ANDAMENTO (ACCIONES EN CURSO): "&COUNTIFS(J9:J208,"En Curso/Andamento") -> AÇÕES EM ANDAMENTO (ACCIONES EN CURSO): 0 | J5: =IFERROR(COUNTIF(J9:J890,"Completa/Concluído")/(COUNTIF(J9:J890,"Planeada/Planejada")+(COUNTIF(J9:J890,"En Curso/Andamento")+(COUNTIF(J9:J890,"Completa/Concluído")+(COUNTIF(J9:J890,"Retardo/Atrasada"))))),"-") -> -
G6: ="AÇÕES PRIORIDADE EM ANDAMENTO (ACCIONES PRIORIDAD EN CURSO): "&COUNTIFS(J9:J208,"En Curso/Andamento",K9:K208,"Y") -> AÇÕES PRIORIDADE EM ANDAMENTO (ACCIONES PRIORIDAD EN CURSO): 0
B8: Nº Ação | Acción | C8: Check List / Imput | D8: Referência (Nº) do Check List / Imput | E8: Problema / Necessidade | F8: KPI | G8: Descrição da Ação | H8: Classificação| Clasificación | I8: Situação da Mudança | J8: Status | K8: Prioridad | L8: Quem|Quién? Responsavel | M8: Quando| Cuando 1° Deadline | N8: Quando| Cuando 2º Deadline | O8: COMENTARIOS | P8: Ação Eficaz | Acción Eficaz?
B9: 1
B10: 2
B11: 3
B12: 4
B13: 5
B14: 6
B15: 7
B16: 8
B17: 9
B18: 10
B19: 11
B20: 12
... B200: 192

Sheet H & S
B2: Checklist de Saúde e Segurança
B3: Referência (Nº) | C3: Pergunta | D3: Orientação | E3: S | F3: N | G3: N/A | H3: Observação (as ações devem ser registradas apenas no Plano de Ação)
B4: Equipamento de Proteção Individual (EPI)
B5: 1 | C5: As Avaliações de Risco ou Análise de Segurança (JSA) foram concluídas para as novas atividades, equipamentos ou estações de trabalho afetdos pela mudança para determinar a necessidade do uso de EPI? Have Risk Assessments or Job Safety Analysis been completed for new activities or equipments or workstations affected by the change to determine the need for PPE? | D5: Baseada na Avaliação de Risco ou Análise de Segurança (JSA): - Atualizar a lista de EPIs necessários para operar o novo equipamento ou realizar a nova tarefa;
B6: 2 | C6: O EPI necessário está disponível para uso dos funcionários? Is required PPE available for employee use?
B7: 3 | C7: O pessoal é treinado sobre os requisitos e uso de EPI? Are personnel trained on PPE requirements and use?
B8: 4 | C8: É realizada checagem médica completa ou teste personalizado para utilização dos devidos EPI? Have personnel completed medical check or test required by certain type of PPE? | D8: Verificar os requisitos locais para uso de respirador, sistemas de proteção contra ruído…
B9: Equipamentos de elevação
B10: 5 | C10: Se for necessário equipamento de elevação (novo ou modificado), é obrigatório: - Planos de inspeção atualizado; - Programas de manutenção preventiva atualizado; - Treinamento antes do uso do equipamento; If new or modified lifting equipment is required, have inspection plans and Preventive Maintenance programs been updated and training provided prior to use? | D10: Elevador, grua, guindastes, empilhadeiras, monta carga, etc.
B11: 6 | C11: Esses equipamentos de elevação (novos ou modificados) estão listados para inspeção periódica por terceiros, de acordo com a legislação local? Are these new or modified lifting equipments listed for periodic inspection by 3rd party in accordance with local regulation?
B12: Proteção contra quedas - Trabalho em altura - Superfícies de passagem
B13: 7 | C13: Onde for necessário trabalho em altura, a estrutura fornece meios adequados de proteção contra quedas? Where work at height will be required, does the design provide for proper means of fall protection? | D13: 35.2.1 Aplica-se o disposto nessa Norma a toda e qualquer atividade com diferença de nível acima de 2,0m (dois metros) do nível inferior, onde haja risco de queda. Uma avaliação de risco deve ser realizada para determinar os riscos potenciais relacionados a um trabalho (permanente ou temporário) acima da superfície do solo e estabelecer meios de proteção contra quedas para proteger os funcionários. Superfícies de trabalho elevadas devem ter guarda-corpos, trilhos intermediários e rodapés, de acordo com os requisitos da legislação local.
B14: 8 | C14: Para os perigos de escorregões e/ou tropeços devido à tração do piso, mudanças de elevação, localização do equipamento, etc. É realizada análise das condições do local de trabalho, controle e mitigação de riscos? Does all slip or tripping hazards due to floor traction, elevation changes, equipment location avoided? | D14: Certifique-se que todos os fios, cabos e mangueiras estejam fora do chão; - As superfícies dos pisos não são ser escorregadias, devido ao uso de produtos químicos; - O piso está livre de superfícies irregulares, rachaduras ou danos; - Há alguma mudança abrupta na tração do piso (por exemplo, de liso para grosso, escorregadio para aderente)?
B15: 9 | C15: Se escadas, escadas de marinheiro, escadas de acesso ao telhado ou escadas fixas forem instaladas, os requisitos exigidos pela legislação local são atendidos? If stairs, ships ladders, roof access hatches or fixed ladders be installed, are requirements of the guidance met? | D15: Certifique-se de que escadas, escadas de marinheiro, escadas de acesso ao telhado e/ou escadas fixas atendam aos requisitos aplicáveis (especialmente a instalação de guarda-corpos; Certifique-se de que o acesso restrito esteja no local para evitar o acesso de pessoas não autorizado ao telhado ou outras áreas perigosas.
B16: 10 | C16: As mudanças de níveis estão claramente marcadas ou identificadas? Have changes in elevation been clearly marked or delineated?
B17: 11 | C17: As portinholas dos pisos, mezaninos ou passarelas foram afixadas com suas informações de carga máxima suportada? Have floor hatches, mezzanines or cat walks been posted with their applicable load ratings?
B18: 12 | C18: Os corredores de pedestres e passagem de veículos são de largura suficiente, de acordo com a leguslação local, adequadamente separados e claramente identificados? Are pedestrian aisles and vehicle aisles of sufficient width, adequately separated, and clearly marked?
B19: 13 | C19: As mangueiras, cabos, cordões, etc. dentro das estações de trabalho estão suspensas ou subterrâneas? Will hoses, cables, cords, etc. within workstations be either overhead or subsurface?
B20: Espaço confinado
B21: 14 | C21: Todos os espaços confinados permitidos e não permitidos foram identificados e documentados? Have all permitted and non permitted confined spaces been identified and documented? | D21: NR 33 33.5.21.1 A organização que possui espaços confinados deve manter no estabelecimento: a) cadastro dos espaços confinados; b) PETs emitidas; e c) inventário de riscos do trabalho em espaço confinado, realizado pela contratada, quando aplicável.
B22: 15 | C22: Os Espaços Confinados Permitidos foram informados? Have Permitted Confined Spaces been posted?
B23: 16 | C23: Os Espaços Confinados Permitidos foram protegidos contra acesso não autorizado? Have Permitted Confined Spaces been secured against unauthorized access?
B24: 17 | C24: As licenças foram revisadas para analisar a inclusão de novos espaços confinados no local? Have permits been revised to reflect the inclusion of new confined spaces on site?
B25: 18 | C25: Os funcionário envolvidos na mudança serão treinados sobre os perigos presentes nos novos espaços confinados? Have affected personnel been trained on hazards present in the new confined spaces?
B26: 19 | C26: Os procedimentos de resgate em espaço confinado estão de acordo com a legislação local e/ou atualizados, conforme necessário? Have confined space rescue procedures been evaluated and revised as necessary?
B27: Outros requerimentos
B28: 20 | C28: O mapeamento de ruído ambiental foi realizado/atualizado? Has baseline noise mapping been performed/updated?
B29: 21 | C29: Foi realizada análise para perigos/ricos relacionados a radiação não ionizante ou outros perigos físicos? Has baseline sampling for non-ionizing radiation and other physical hazards been performed? | D29: Como laser, ultrasom, radiação ultravioleta (UV)…
B30: 22 | C30: Os estudos de iluminação foram realizados/atualizados? Have illumination studies been performed/updated?
B31: 23 | C31: Se os funcionários da área precisam ser colocados em um programa de vigilância médica, os requisitos da legislação local são atendidos? If operators in the area need to be placed into a medical surveillance program, are requirements of the guidance met? | D31: Atualizar o PCMSO com a lista de funcionários envolvidos na mudança e os requisitos de monitoramento.
B32: 24 | C32: Se equipamentos de monitoramento adicionais foram identificados, eles foram adquiridos e instalados? If additional monitoring equipment have been identified, have they been purchased and installed?
B33: 25 | C33: O desempenho do sistema de ventilação e exaustão foram avaliados? Has performance of the ventilation system been evaluated? | D33: Certifique-se de que o desempenho da ventilação/exaustão atenda aos requisitos locais após as mudanças.
B34: 26 | C34: A ventilação e exaustão atendem aos requisitos de regulamentação local, se houver? Does the ventilation meet local regulation requirements if any?
B35: 27 | C35: O potencial de exposição ocupacional a patógenos transmitidos pelo sangue foram avaliados, o programa de saúde foi atualizado e o treinamento fornecido aos funcionários, conforme necessário? Has the potential for occupational exposure to Bloodborne Pathogens been evaluated, and program updated and training provided as required?
D37: Total | E37: =COUNTA(E4:E35) -> 0 | F37: =COUNTA(F4:F35) -> 0 | G37: =COUNTA(G4:G35) -> 0 | H37: =SUM(E37:G37) -> 0
D38: Total | E38: =IFERROR(E37/$H$37,"-") -> - | F38: =IFERROR(F37/$H$37,"-") -> - | G38: =IFERROR(G37/$H$37,"-") -> -

Sheet Chemical
B2: Checklist de Gerenciamento de Produtos Químicos
B3: Referência (Nº) | C3: Pergunta | D3: Orientação | E3: S | F3: N | G3: N/A | H3: Observação (as ações devem ser registradas apenas no Plano de Ação)
B5: 1 | C5: Se novos produtos químicos tiverem que ser introduzidos, alterados ou modificados, os requisitos do Programa de Gerenciamento de Produtos Químicos do Departamento Global de EHS são aplicados? If new chemicals have to be introduced, changed or modified, are requirements of the Chemical Management Program from the Global EHS Department applied? | D5: O Programa de Gerenciamento de Produtos Químicos está disponível na Intranet do Departamento Global de EHS.
B6: 2 | C6: Os produtos químicos passaram pelo processo de aprovação/aquisição do Plano de Gerenciamento de Produtos Químicos do EHS local? Have the chemicals gone through the site/service Chemical Management Plan's procurement and approval process?
B7: 3 | C7: Verifique se os produtos químicos a serem usados não estão na lista de produtos químicos proibidos ou restritos da Essilor. Check that the chemicals intended to be used are not on the Essilor banned or restricted list of chemicals? | D7: Esta lista está disponível na Intranet do Departamento Global de EHS. Se os produtos químicos estiverem listados em uma dessas 2 listas, entre em contato com seu gerente de EHS local.
B8: 4 | C8: O Regulamento sobre registro, avaliação, autorização e restrição de produtos químicos (REACH) é a principal lei da UE para proteger a saúde humana e o meio ambiente dos riscos que os produtos químicos podem representar. Regulamento REACH: Verifique se os produtos químicos não contêm nenhuma Substância de Alta Preocupação (SVHC) atualmente listada na lista da Agência Europeia de Produtos Químicos (ECHA)? REACH regulation: Check that the chemicals do not contain any Substance of Very High Concern (SVHC) currently listed on the European Chemical Agency (ECHA) list? | D8: Esta lista da ECHA é atualizada regularmente e está disponível em: https://echa.europa.eu/candidate-list-table Se o produto químico contiver uma SVHC, entre em contato com seu gerente de EHS nacional ou regional ou com o Departamento de EHS global
B9: 5 | C9: As Fichas de Informações de Produtos Químicos (FISPQ) adequadas estão disponíveis para os novos produtos químicos? Are proper Material Safety Data Sheets (MSDS) available for the new chemicals? | D9: Verifique se as FISPQ estão disponíveis no idioma local e no formato adequado de acordo com a legislação local.
B10: 6 | C10: Os perigos dos novos produtos químicos foram devidamente avaliados para garantir que instalações, equipamentos e controles adequados estejam em vigor para manuseá-los com segurança? Have the hazards of the new chemicals been properly assessed to ensure that adequate facilities, equipment and controls are in place to safely handle?
B11: 7 | C11: A lista de produtos químicos aprovados (ACL) do site foi atualizada com os novos produtos químicos? Has the site Approved Chemical List (ACL) been updated with the new chemicals? | D11: A atualização da Lista de Produtos Químicos Aprovados (ACL) do site, deve ser feita assim que um produto químico for aprovado pelo gerente de EHS local e pela equipe médica.
B12: 8 | C12: Foram estabelecidos procedimentos seguros para armazenamento, distribuição, uso e descarte desses produtos químicos? Have safe procedures for storage, dispensing, use and disposal been established for these chemicals?
B13: 9 | C13: As salas, armários e recipientes classificados estão devidamente identificados e disponibilizados para armazenamento seguro de produtos químicos? Have properly rate rooms, cabinets and containers been indentified and made available for safe storage of chemicals?
B14: 10 | C14: Foram tomadas providências para contenção secundária e segregação correta? Have provisions been made for secondary containment & segregation?
B15: 11 | C15: Existem lava-olhos e chuveiros de segurança adequados nas áreas onde produtos químicos perigosos serão usados? Are proper eyewash stations & safety showers available in the areas where hazardous chemicals are to be used? | D15: Verifique os requisitos da legislação local.
B16: 12 | C16: Estão disponíveis suprimentos adequados para conter derramamentos/vazamentos? Are adequate spill response supplies available?
B17: 13 | C17: Os requisitos de rotulagem de perigos de recipientes químicos foram identificados e implementados? Has chemical container hazard labeling requirements been identified and in place?
B18: 14 | C18: As tubulações com passagem de produtos químicos estão devidamente rotuladas? Is chemical piping properly labeled?
B19: 15 | C19: Os funcionários envolvidos na mudança foram treinados sobre os perigos associados aos novos produtos químicos e como trabalhar com eles com segurança? Have affected employees been trained on the hazards associated with the new chemicals and how to work with them safely?
B20: 16 | C20: A hierarquia de controles (engenharia - administrativo - EPI) foi observada para minimizar ou eliminar a exposição a esses produtos químicos? Have the hierarchy of controls (e.g., engineering, administrative & PPE) been observed to minimize or eliminate exposure to these chemicals?
B21: 17 | C21: Foi realizada uma análise qualitativa de exposição ao produtos quimicos para determinar o risco de exposição do funcionário a esses produtos químicos? Has a qualitative Industrial Hygiene Risk Assessment (IHRA) been performed to determine employee exposure risk to these chemicals?
B22: 18 | C22: Com base nos resultados da análise qualitativa de exposição ao produtos quimicos, foi realizada análise quantitativa dos níveis de exposição química dos funcionários? Based on the results of the qualitative IHRA, has sampling been performed to quantify employee chemical exposure levels?
B23: 19 | C23: Com base nos resultados da análise qualitativa de exposição ao produtos quimicos,os funcionários da área precisarão ser inseridos ou ter os exames do PCMSO alterados? Based on the results of the qualitative IHRA, will operators in the area need to be placed into a medical surveillance program?
B24: Transporte de químicos
B25: 20 | C25: Se algum produto químico tiver que ser enviado do local, os requisitos da legislação local foram atendidos? If any chemicals have to be shipped from site, are requirements of the guidance met? | D25: Inclua FISPQ e ficha de emergência com o material durante o envio. Se necessário, entre em contato com o Departamento Global de EHS para obter orientação sobre Transporte de Materiais Perigosos, DOT e IATA para remessa internacional e com o EHS Local para envio nacional.
B26: 21 | C26: Se a mudança envolver a importação ou exportação de quaisquer novos produtos químicos, os requisitos da orientação foram atendidos? If the change involve the import or export of any new chemicals, are requirements of the guidance met? | D26: Adicionar à lista de importação e exportação de sites. Verifique se não há proibições ou restrições do país sobre produtos químicos a serem exportados/importados. Existem registros de produtos específicos do país necessários? Se necessário, entre em contato com o Departamento Global de EHS para obter orientação sobre Transporte de Materiais Perigosos
D28: Total | E28: =COUNTA(E4:E26) -> 0 | F28: =COUNTA(F4:F26) -> 0 | G28: =COUNTA(G4:G26) -> 0 | H28: =SUM(E28:G28) -> 0
D29: Total | E29: =IFERROR(E28/$H$28,"-") -> - | F29: =IFERROR(F28/$H$28,"-") -> - | G29: =IFERROR(G28/$H$28,"-") -> -

Sheet Eletrical
B2: Checklist de Segurança Elétrica
B3: Referência (Nº) | C3: Pergunta | D3: Orientação | E3: S | F3: N | G3: N/A | H3: Observação (as ações devem ser registradas apenas no Plano de Ação)
B5: 1 | C5: Todas as instalações elétricas estão identificadas? Are all electrical installations identified? | D5: Certifique-se de que todas as instalações elétricas estejam de acordo com os padrões, classificações e requisitos de rotulagem aplicáveis. Certifique-se de que as tensões nominais e os circuitos de alimentação foram marcados nos painéis de disjuntores, controladores de motor e receptáculos. As quedas pendentes foram avaliadas para garantir um projeto adequado e controle de tensão. Os receptores elétricos foram testados para garantir fiação, tensão, tensão nominal e resistência adequadas. Os diretórios do disjuntor são correspondentes, corretos e completos? Existem desenhos elétricos do local, do prédio, do departamento ou do equipamento atualizados.
B6: 2 | C6: A rede de energia da instalação da distribuição ou o painel de ramificação para a desconexão principal do equipamento foram verificados quanto às conexões e rotulagem corretas? Has the facility power network from the distribution or branch panel to the equipment main disconnect been verified for correct connections and labeling?
B7: 3 | C7: Existe alguma trava que bloqueia a energia principal e que seja facilmente acessível, devidamente rotulada e capaz de desconectar todas as fontes de energia elétrica do equipamento? Is there a lockable main power disconnect that is readily accessible, properly labeled, and capable of disconnecting all electrical power sources to the equipment?
B8: 4 | C8: Todos os painéis elétricos têm acesso desimpedido? Do all electrical panels have unimpeded access? | D8: Painéis elétricos e seccionadores devem ter, no mínimo, 1 metro de espaço desobstruído à sua frente ou mais se exigido pela regulamentação local.
B9: 5 | C9: Todos os painéis elétricos estão fechados/seguros? Do all electrical panels are closed/secured?
B10: 6 | C10: Todas as fontes de energia foram devidamente identificadas e marcadas? Have all energy sources been properly identified and marked?
B11: 7 | C11: As tomadas elétricas foram testadas para garantir fiação, tensão, tensão nominal e resistência adequadas? Have electrical receptacles been tested to ensure proper wiring, tension, nominal voltage and resistance?
B12: 8 | C12: As tensões nominais e os circuitos de alimentação foram marcados nos painéis de disjuntores, controladores de motor e receptáculos? Have nominal voltages and feeder circuits been marked on breaker panels, motor controllers and receptacles?
B13: 9 | C13: Os diretórios de disjuntores estão correspondentes, corretos e completos? Are breaker directories posted, accurate and complete?
B14: 10 | C14: Há diagrama unifilar disponíveis para circuitos das áreas? Are single-line diagram (SLD)drawings available for circuits in the area?
B15: 11 | C15: Existe dispositivos de Proteção contra Surtos (DPS) que conseguem detectar sobretensões transitórias na rede elétrica causados por descargas atmosféricas instalados e operando de acordo com o projeto? Is a ground fault circuit interrupt (GFCI) system installed & operating per design, where applicable?
B16: 12 | C16: A continuidade do aterramento foi verificada? (Cintas de aterramento/ligação instaladas e verificadas quando aplicável) Has ground continuity been verified? (Ground/bond straps installed & verified where applicable)
B17: 13 | C17: Se necessário, os interruptores de falha de aterramento são instalados e testados? If needed, are ground fault interrupters installed and tested?
B18: 14 | C18: Os condutores expostos são protegidos conforme exigências locais? Are exposed conductors guarded as required?
B19: 15 | C19: As lumináras pendentes foram avaliadas para garantir projeto adequado e o controle de tensão? Have pendant drops been evaluated to ensure proper design and tension control?
B20: ATEX (Ante-Explosão) and Arco Elétrico
B21: 16 | C21: Se instalados em locais classificados como perigosos ou expostos a vapores inflamáveis, todos os componentes elétricos são classificados para locais perigosos, de acordo com os requisitos ATEX (ante explosão)? If installed in hazardous classified locations or exposed to flammable vapors, are all electrical components rated for hazardous locations in accordance with ATEX requirements? | D21: Material elétrico EX para atmosferas explosivas.
B22: 17 | C22: Se aplicável, as marcações do raio de explosão do arco elétrico foram aplicadas aos controladores de motores, disjuntores e outras instalações elétricas? When applicable (e.g. NFPA 70 ), have Arc Blast field markings been applied to motor controllers, breakers and other applicable installations?
B23: 18 | C23: Os cálculos de energia incidente de uma explosão de arco foram realizados? Have arc blast incident energy calculations been performed?
B24: 19 | C24: A fiação/equipamento elétrico estão protegidos contra prováveis fontes de vazamento de líquido? Is electrical wiring / equipment protected from probable liquid leak sources?
B25: Lock-Out / Tag-Out (LOTO)
B26: 20 | C26: Os meios primários de bloqueio LOTO são compatíveis? Are primary means of disconnects LOTO compatible?
B27: 21 | C27: Foram desenvolvidos procedimentos LOTO específicos para cada equipamento? Have equipment-specific LOTO procedures been developed? | D27: Como fontes elétricas, mecânicas, hidráulicas, químicas ou térmicas.
D29: Total | E29: =COUNTA(E4:E27) -> 0 | F29: =COUNTA(F4:F27) -> 0 | G29: =COUNTA(G4:G27) -> 0 | H29: =SUM(E29:G29) -> 0
D30: Total | E30: =IFERROR(E29/$H$29,"-") -> - | F30: =IFERROR(F29/$H$29,"-") -> - | G30: =IFERROR(G29/$H$29,"-") -> -

Sheet Organizational
B2: Checklist de Segurança Organizacional
B3: Referência (Nº) | C3: Pergunta | D3: Orientação | E3: S | F3: N | G3: N/A | H3: Observação (as ações devem ser registradas apenas no Plano de Ação)
B4: Resposta a Emergência
B5: 1 | C5: Essa mudança afetará a capacidade do pessoal de responder com segurança durante uma crise ou situação de emergência? Will this change affect the ability of personnel to respond safely during a crisis or an emergency situation? | D5: Se sim, complete a planilha "Emergency Prepardness - Fire Prevention & Protection"
B6: 2 | C6: Se o plano de resposta a emergências do local for afetado, os requisitos da legislação foram atendidos? If the site emergency response plan is impacted, are requirements of the guidance met? | D6: Verifique e atualize os documentos relacionados a situação de emergência, tais como: Plano de Ação de Emergência (PAE), Plano de Contingência de Negócios, Brigada de Emergência, reações em caso de incêndio, explosão, condições climáticas extremas, terremoto, ameaça de bomba… devido a mudança.
B7: Segurança
B8: 3 | C8: Se a segurança geral da planta ou do pessoal for afetada, os procedimentos, documentos e organização são atualizados? If the overall Safety of the plant or personnel be impacted, are procedures, documents, organization updated?
B9: 4 | C9: Se as inspeções de segurança programadas de itens como chuveiros de segurança, extintores de incêndio, guindastes, escadas, etc. sofrerem impacto, os requisitos da legislação são atendidos? If scheduled safety inspections of items such as safety showers, fire extinguishers, hoists, ladders, etc be impacted, are requirements of the guidance met? | D9: Atualizar documentos relevantes e treinar nova(s) pessoa(s)
B10: 5 | C10: Se a emissão e encerramento das permissões de segurança para trabalho perigosos (permissão de trabalho a quente, plano de prevenção...) forem afetadas, os requisitos da legislação são atendidos? If completion of Safety permits (Hot work permit, prevention plan…) be impacted, are requirements of the guidance met? | D10: Atualizar documentos relevantes e treinar nova(s) pessoa(s)
B11: 6 | C11: Se a mudança afetar a capacidade de garantir a Manutenção Preventiva, os requisitos da legislação são atendidos? If the change affect the ability to ensure Preventive Maintenance, are requirements of the guidance met?? | D11: Atualizar documentos relevantes e treinar nova(s) pessoa(s)
B12: 7 | C12: Se as reuniões de segurança antes das Operações de Alto Risco ou Operações envolvendo Contratadas forem impactadas, os requisitos da orientação são atendidos? If safety meetings before High Risk Operations or Operations involving Contractors be impacted, are requirements of the guidance met? | D12: Atualizar documentos relevantes e treinar nova(s) pessoa(s)
B13: 8 | C13: Se a mudança afetar a(s) pessoa(s) responsável(is) pela realização de auditorias de segurança ou revisões, os requisitos da legislação foram atendidos? If the change impact a person(s) responsible for conducting other safety audits or reviews, are requirements of the guidance met? | D13: Atualizar documentos relevantes e treinar nova(s) pessoa(s)
B14: Meio Ambiente
B15: 9 | C15: Se a mudança afetar a posição de uma pessoa responsável por tarefas ambientais, como amostragem, licenciamento, detecção de vazamento, manutenção de registros, inspeções, etc., os requisitos da legislação foram atendidos? If the change impact a person(s) position who is responsible for environmental tasks such as sampling, permitting, leak detecting, recordkeeping, inspections, etc, are requirements of the guidance met? | D15: Atualizar documentos relevantes e treinar nova(s) pessoa(s)
B16: 10 | C16: Se o descarte de resíduos, limpeza, inspeções, área de armazenamento de produtos químicos, etc. forem afetados, os requisitos da legislação são atendidos? If waste disposal, housekeeping, inspections, chemical storage area, etc be affected, are requirements of the guidance met? | D16: Atualizar documentos relevantes e treinar nova(s) pessoa(s)
B17: 11 | C17: Se a mudança afetar a capacidade de determinar desvios ou violações de licenças ambientais aplicáveis a unidade, os requisitos da legislação são atendidos? If change impact the ability to determine deviations or violations of environmental permits applicable to site, are requirements of the guidance met? | D17: Atualizar documentos relevantes e treinar nova(s) pessoa(s)
B18: Higiene Ocupacional e impacto na saúde do trabalhador
B19: 12 | C19: Se a mudança afetar a capacidade de realizar monitoramento ou coleta de dados de exposição de Higiene Industrial, os requisitos da legislação são atendidos? If the change affect the ability to perform monitoring or gathering of IH exposure data, are requirements of the guidance met? | D19: Atualizar documentos relevantes e treinar nova(s) pessoa(s)
B20: 13 | C20: Se os cronogramas de coleta de dados forem afetados, os requisitos da legislação são atendidos? If schedules of data gathering be affected, are requirements of the guidance met? | D20: Atualizar documentos relevantes e treinar nova(s) pessoa(s)
B21: 14 | C21: Se o monitoramento da saúde for afetado, os requisitos da legislação são atendidos? If health monitoring is affected, are requirements of the guidance met? | D21: Atualizar documentos relevantes e treinar nova(s) pessoa(s)
B22: Treinamento de EHS
B23: 15 | C23: Se o treinamento sobre tópicos de EHS for afetado (cronograma, entrega, rastreamento, atualização de conteúdo e material de treinamento...), os requisitos da legislação são atendidos? If training on EHS topics be impacted (schedule, delivering, tracking, update of training content and material…), are requirements of the guidance met? | D23: Atualizar documentos relevantes e treinar nova(s) pessoa(s)
B24: 16 | C24: Se o treinamento de funcionários novos, realocados ou transferidos forem afetados, os requisitos da legislação são atendidos? If training for new or relocated personnel be impacted, are requirements of the guidance met? | D24: Atualizar documentos relevantes e treinar nova(s) pessoa(s)
B25: EHS - Outros
B26: 17 | C26: Se houver algum outro requisito de conformidade ou gerenciamento que possa ser afetado por essa mudança, eles foram atualizados? If there is any other compliance or management requirements which would be affected by this change, have they been updated?
B27: 18 | C27: Se os procedimentos ou a documentação precisarem ser modificados para levar em consideração essa mudança, essas atualizações estão concluídas? If procedures or documentation need to be modified to take into account this change, are these updates completed?
D29: Total | E29: =COUNTA(E4:E27) -> 0 | F29: =COUNTA(F4:F27) -> 0 | G29: =COUNTA(G4:G27) -> 0 | H29: =SUM(E29:G29) -> 0
D30: Total | E30: =IFERROR(E29/$H$29,"-") -> - | F30: =IFERROR(F29/$H$29,"-") -> - | G30: =IFERROR(G29/$H$29,"-") -> -

Sheet Ergonomics
B2: Checklist de Ergonomia
B3: Referência (Nº) | C3: Pergunta | D3: Orientação | E3: S | F3: N | G3: N/A | H3: Observação (as ações devem ser registradas apenas no Plano de Ação)
B4: Necessidade de análises ergonômicas
B5: 1 | C5: A alteração implica impactos ao nível do posto de trabalho, postura do trabalhador, equipamentos, carga a transportar, movimentos repetitivos, organização do trabalho (em termos de horário, turno, competências, competências e conhecimentos, procedimento…)…? Does the change imply impacts regarding workstation, worker posture, equipment, load to carry, repetitive movements, work organization (in terms of schedule, shift, competencies, skills and knowledge, procedure…) …? | D5: Uma análise ergonômica deve ser realizada e um plano de ações corretivas deve ser estabelecido.
B6: 2 | C6: A interface com outros equipamentos foi estudada? Has interfacing with others equipments been studied ? | D6: Se for o caso, atualize a análise ergonômica dos equipamentos próximos.
B7: Equipamento, instalação & Projeto
B8: Tamanho e layout das estações de trabalho (sentado e em pé) e posturas
B9: 3 | C9: O tamanho e o layout da estação de trabalho atendem aos padrões? Os controles manuais estão posicionados corretamente e projetados para permitir uma boa postura dos membros superiores? Alguma parte do corpo está exposta a pressão constante? Does the workstation size and layout meet standards ? Are hand controls correctly placed and designed to allow a good upper limb posture ? Is any body part exposed to constant pressure ? | D9: Ver orientação para aspectos antropométricos (medidas primárias: peso, altura, dobras cutâneas e circunferências e medidas secundárias: índice de massa corpórea, peso ideal e soma de dobras cutâneas) Leve em consideração as áreas de alcance. Consulte as recomendações para as posições sentada e sentada/em pé.
B10: 4 | C10: O projeto e a instalação da estação de trabalho minimizam as más posturas dos pulsos, mãos, braços, pescoço e costas? O espaço de trabalho permite uma postura estável e neutra? Does the workstation design and installation minimize poor postures of the wrists, hands, arms, neck and back ? Does the workspace allow a stable, neutral posture ? | D10: A posição de todas essas partes do corpo deve estar próxima da posição natural. Ver orientação para aspectos antropométricos.
B11: 5 | C11: Há espaço suficiente para as pernas na postura sentada ou em pé? Is there sufficient leg room for sitting or sitting-standing postures ? | D11: Mantenha as pernas relaxadas e apoiadas na frente do corpo.
B12: 6 | C12: A cadeira está em bom estado e ajustável? Apoiando as costas? Equipada com um encosto? Altura devidamente ajustada à pessoa e à tarefa a realizar ? As pernas e os pés da pessoa estão bem posicionados e apoiados? Is the chair:In good condition and adjustable ? Supporting the back ? Equipped with a back rest ? Height properly adjusted for the person and the task to be done ? Are the person's legs and feet properly positioned and supported ? | D12: O encosto da cadeira deve apoiar firmemente a região lombar e a parte superior das costas. Os quadris e os joelhos devem estar ligeiramente na mesma altura. As pernas devem formar um ângulo de aproximadamente 90°; deve haver um espaço entre a parte de trás dos joelhos e a borda do assento, os pés devem estar apoiados no chão ou no apoio para os pés. Consulte a legislação local para cadeiras com apoio lombar, apoios de braços.
B13: 7 | C13: O trabalho em pé é organizado para limitar o impacto negativo? Is standing work organized to limit the negative impact ? | D13: Para posturas de trabalho em pé, é sugerido palmilha antifadiga e instalação de tapete antifadiga.
B14: Acesso e movimento em torno da estação de trabalho
B15: 8 | C15: O funcionário pode acessar facilmente as superfícies de trabalho? O espaço de trabalho está adequado à tarefa? Há espaço suficiente para o funcionário trabalhar? Can employee easily access work surfaces ? Is the workspace fitting with the task ? Is there sufficient space for employee to work ? | D15: Ver orientação para aspectos antropométricos (medidas primárias: peso, altura, dobras cutâneas e circunferências e medidas secundárias: índice de massa corpórea, peso ideal e soma de dobras cutâneas)
B16: 9 | C16: Existem espaços funcionais adequados no local de trabalho para reduzir a necessidade de torcer o tronco ou assumir outras posturas incômodas? Existem unidades de armazenamento suficientes para arquivar a documentação ou guardar as ferramentas? Are there adequate functional clearances around the workplace to reduce needs for twisting the trunk or taking other awkward postures ? Are there enough storage units to file away the documentation or to put away the tools ?
B17: 10 | C17: Há espaço suficiente entre as diferentes estações de trabalho? Is there enough room between the different workstations ? | D17: Veja recomendação/legislação para layout de corredores.
B18: Informações (marcações e identificações)
B19: 11 | C19: As instruções de processo, ou informações necessárias para realizar o trabalho ou para usar novos equipamentos, estão disponíveis na estação de trabalho? É necessário instalar novas informações devido à mudança? Are process instructions, or information, needed to carry out the work or to use new equipment, be available on workstation ? Is it necessary to install new information due to the change ? | D19: Forneça informações claras, bem marcadas e fáceis de lembrar. A informação de diferentes canais/modalidades estão integradas?
B20: 12 | C20: São necessárias marcações ou identificações para minimizar os riscos? Os símbolos de perigo ou outros avisos estão localizados em áreas apropriadas? Are marking or identification needed in order to minimize risks ? Are hazard symbols or other notices located in appropriate areas ? | D20: Ex.: - corredores de pedestres e corredores de veículos devem ser claramente marcados; - uso de símbolos de perigo; - utilização de taxa de carga para prateleiras de armazenamento.
B21: 13 | C21: A informação existente satisfaz os requisitos do operador? Does the existing information satisfy the operator's requirements ? | D21: As instruções verbais ou escritas estão na linguagem correta e são facilmente compreendidas? A taxa de fluxo de informações está de acordo com a tarefa? Quantas fontes de informação o funcionário utiliza para trabalhar? Os dados estão prontamente disponíveis, devidamente formulados e claros?
B22: 14 | C22: A exibição visual está bem posicionada? A parte superior dos visores está situada de forma a ficar ligeiramente abaixo do nível dos olhos? Are the visual display well positioned ? Is the top of the displays situated in such a way that it is situated slightly below eye level ? | D22: Deve estar situado à frente do usuário, a uma distância adequada entre 30 e 50 cm. O pescoço não deve estar inclinado para cima, para baixo, para a esquerda ou para a direita, mas em uma posição neutra. As pessoas geralmente se sentem mais confortáveis com o monitor no comprimento do braço. Para usuários de lentes multifocal geralmente é mais apropriado ter o monitor o mais baixo possível. O monitor deve estar alinhado ou de acordo com a pessoa para reduzir a torção do tronco e o alcance de mãos.
B23: 15 | C23: O uso do teclado e do mouse está sobrecarregando o pulso? Are keyboard and mouse in use putting a strain on the wrist ? | D23: Os pulsos devem estar retos em uma posição natural, não torça os pulsos para a direita ou para a esquerda. Para digitação, os antebraços devem estar paralelos ao chão. Para leitura e escrita, a superfície da mesa deve ser um pouco mais alta. Com um laptop, use teclado, mouse e suporte externos para minimizar as restrições ergonômicas. Veja as recomendações ergonômicas.
B24: 16 | C24: A tela está livre de reflexos? A tela está instalada na frente de uma janela? Is the screen free of glare ? Is the screen installed in front of a window ? | D24: Recomenda-se instalar a tela: - perpendicular às janelas; - não muito perto de uma parede para favorecer a visão de longe (os músculos dos olhos devem poder descansar) quando as pessoas estão olhando para o visor;
B25: 17 | C25: Caso tenham sido identificados equipamentos adicionais de monitoramento, eles estão posicionados corretamente? Os controles estão próximos de seus displays correspondentes? If additional monitoring equipments have been identified, are they correctly positioned ? Are controls close to their corresponding displays ? | D25: Eles devem ser instalados de tal forma: a parte superior da tela está aproximadamente no nível dos olhos, não há movimento de torção do pescoço e/ou tronco.
B26: Equipamentos e ferramentas
B27: 18 | C27: Caso a mudança envolva novos equipamentos, foram verificados os requisitos da planilha “Equipament”? If the change involves new equipment, are the requirements of the "Equipment" spreadsheet been verified? | D27: Confira todos os requisitos da planilha de "Equipament".
B28: 19 | C28: São fornecidas instruções adequadas, guia do usuário e guia de manutenção? Are proper instructions, user guide and maintenance guide provided ?
B29: 20 | C29: A manutenção pode acessar facilmente todas as partes do equipamento para tarefas de manutenção de rotina? Can maintenance easily access to all parts of the equipment for routine maintenance tasks?
B30: 21 | C30: Esforços significativos precisam ser realizados? Do significant efforts need to be carried out ? | D30: Instruções simples e documentação de processo que fornecem informações sobre a execução de uma tarefa devem ser fornecidos para reduzir a alta demanda física. Consulte as normas para obter o peso máximo recomendado.
B31: Fatores ambientais
B32: Barulho
B33: 22 | C33: É necessária uma atualização do mapa de ruído devido à mudança? Is an update noise map needed due to the change ? | D33: O nível de ação de ruído local a ser aplicado é: 85 dB(A) para a maioria dos países. O nível recomendado para oficina é < 85 dB(A). Optar, primeirramente, pela instalação de equipamentos de redução de ruído coletivo, para então definiar o uso de equipamentos de proteção individual (EPI).
B34: Clima
B35: 23 | C35: Existem temperaturas extremas em algumas áreas? Se for o caso, essas áreas são confinadas? Foram implementadas medidas de segurança para que os funcionários trabalhem confortavelmente nessas condições? Are there extreme temperatures existing in some areas ? If it's the case, are these areas confined ? Have safety measures been implemented for employees to work comfortably in these conditions ? | D35: Local de trabalho frio: câmara fria, trabalho em área refrigerada. Local de trabalho quente: secadora, forno. Roupas e dispositivos de proteção estão disponíveis para funcionários em ambientes extremos? A exposição pode ser reduzida por meio de períodos de descanso em áreas adequadas ou por meio de rodízio de funcionários?
B36: Iluminação
B37: 24 | C37: O nível geral de iluminação respeita as normas recomendadas? Does the overall lighting level respect the recommended standards ? | D37: O nível de luz recomendado para oficina é de 300 lux, para leitura de cerca de 500 lux e para trabalho de computador cerca de 300 lux no mínimo. Deve ser corrigido pelo coeficiente baseado na atividade (ver normas de iluminação).
B38: 25 | C38: Brilhos, reflexos ou contrastes indesejáveis são minimizados na tarefa visual? Há brilho excessivo ou ofuscamento no espaço de trabalho? Are undesirable glares, reflections or contrasts minimized in the visual task ? Is there excessive brightness or glare in the workspace ? | D38: O contraste da tarefa visual deve ser ajustado à tarefa. Sem ofuscamento (diminui a legibilidade da tarefa visual).
B39: 26 | C39: A localização do equipamento de iluminação foi avaliada para se adequar à mudança? Have lighting equipment location been evaluated to fit the change ?
B40: 27 | C40: Os equipamentos de iluminação foram limpos? Have lighting equipment been cleaned ? | D40: Um dispositivo de iluminação sujo tem um desempenho muito ruim e causa fadiga ocular.
B41: 28 | C41: A lâmpada de iluminação tem uma reprodução de cor >= 80 para local industrial e >= 85 para escritórios? Have the lighting lamp a color rendering >= 80 for industrial local and >= 85 for offices ? | D41: Uma renderização de cores < 80 não permite ver as cores corretamente e pode causar fadiga ocular a longo prazo. Verifique a renderização de cores marcada na lâmpada fluorescente.
...

Sheet Environment
B2: Checklist de Meio Ambiente
B3: Referência (Nº) | C3: Pergunta | D3: Orientação | E3: S | F3: N | G3: N/A | H3: Observação (as ações devem ser registradas apenas no Plano de Ação)
B4: Emissões atmosféricas
B5: 1 | C5: Se houver uma adição ou alteração em uma fonte de emissão atmosférica existente, os requisitos da orientação são atendidos? If there is an addition or change to an existing air emission source, are requirements of the guidance met? | D5: Avalie o impactos das fontes de emissão quanto aos impactos das emissões atmosféricas definidos licença ambiental e na legislação local. Entre em contato com o EHS local para obter uma atualização da documentação em caso de impactos em tais licenças.
B6: 2 | C6: Se houver alguma ventilação e/ou extaustão necessária, chaminés, entrada de ar através de paredes ou telhado, os requisitos da legislação são atendidos? If there is any required venting, stacks, penetrations through walls or roof, are requirements of the guidance met? | D6: Avalie os impactos de tais trabalhos no material da parede ou telhado para a resistência ao fogo. Se necessário, entre em contato com o EHS Global, EHS Local ou seguradora contra incêndio (FM Global).
B7: 3 | C7: Se um equipamento de controle de poluição do ar for adicionado/modificado/usado, os requisitos da legislação local são atendidos? If air pollution control equipment be add/modified/used, are requirements of the guidance met? | D7: Desenvolva procedimentos operacionais, que incluam parâmetros operacionais de equipamentos de controle, para equipamentos. Os procedimentos devem identificar quem deve ser notificado quando ocorrerem transtornos ou mau funcionamento que possam afetar as emissões atmosféricas ou a conformidade. Avalie o equipamento de controle para determinar a necessidade de peças sobressalentes críticas e desenvolva uma lista dessas peças e tenha peças sobressalentes críticas prontamente disponíveis. Treine os operadores de equipamentos sobre os procedimentos. Adicione equipamentos ao programa de manutenção preventiva e/ou inspeção, se aplicável.
B8: Químicos
B9: 4 | C9: Caso a mudança envolver o uso de algum produto químico, são verificados os requisitos da planilha “Químico”? If the change involve the use of any chemicals, are the requirements of the "Chemical" spreadsheet verified? | D9: Verifique todos os requisitos da planilha “Químico”.
B10: Consumo de Energia
B11: 5 | C11: Se a mudança acarretar aumento ou redução do consumo de energia, os requisitos da orientação são atendidos? If the change lead to an increase or reduction of Energy consumption, are requirements of the guidance met? | D11: Estimar e documentar o aumento ou redução potencial de energia. Em caso de aumento significativo do uso de energia, consulte o líder do Projeto de Consumo de Energia/Água ou o Departamento EHS Local.
B12: 6 | C12: Se a alteração tiver impacto no consumo de Energia, atualize o Mapa de Energia da unidade. If the change has an impact on Energy consumption, update the Energy Map of the site | D12: Se o seu site tiver um mapa de energia, atualize-o. Verifique também a oportunidade de instalar medidores de consumo de energia para obter métricas e atualizar o consumo geral do local.
B13: Permissão ou outros requisitos regulamentares
B14: 7 | C14: Se a mudança levar à solicitação de uma nova licença ou modificada (ar, água, águas pluviais, energia, operação, armazenamento de produtos químicos, uso de produtos químicos sob o regulamento REACH), os requisitos da planilha "Compliance" são verificados? If the change lead to the application for a new or modified permit (air, water, stormwater, energy, operating, ICPE, IPPC, chemical storage, chemical usage under REACH regulation), are the requirements of the "Compliance" spreadsheet verified? | D14: Verifique todos os requisitos da planilha "Compliance".
B15: Consumo de Água
B16: 8 | C16: Caso a mudança leve a um aumento ou redução do consumo de Água, os requisitos da legislação são atendidos? If the change lead to an increase or reduction of Water consumption, are requirements of the guidance met? | D16: Estimar e documentar o potencial aumento ou redução de água. Em caso de aumento significativo do uso de energia, consulte o líder do Projeto de Consumo de Energia/Água ou o Departamento EHS Local.
B17: 9 | C17: Se a alteração tiver impacto no consumo de Água, atualize o Mapa de Água da unidade. If the change has an impact on Water consumption, update the Water Map of the site | D17: Se o seu site tiver um mapa de água, atualize-o. Verifique também a oportunidade de instalar hidrômetros ou outros medidores para obter métricas e atualizar o consumo geral do local.
B18: Resíduos
B19: 10 | C19: Se a mudança gerar fluxos de resíduos novos ou adicionais ou modificar um fluxo de resíduos existente, os requisitos da legislação foram atendidos? If the change generate any new or additional waste streams or modify an existing waste stream, are requirements of the guidance met? | D19: Revise os requisitos de descarte adequados de EHS. Avaliar os custos associados à disposição e tratamento dos resíduos da produção. Entre em contato com o fornecedor local de resíduos e documente o perfil dos resíduos. Atualizar a matriz de resíduos dos sites. Os resíduos precisam de um perfil de resíduos?
B20: 11 | C20: Se for necessária uma área de armazenamento de resíduos nova ou modificada dentro do local, os requisitos da legislação são atendidos? If a new or modified waste accumulation area is required inside the site, are requirements of the guidance met? | D20: 1. Configuração de área de armazenamento nova ou modificada. Providencie sinalização adequada. Atualize a matriz de armazenamento de resíduos da unidade e adicione à inspeção semanal. 2. Revisar os requisitos de treinamento atuais dos departamentos. Adicionar treinamento de gestão resíduos perigosos ao plano de treinamento dos funcionários.
B21: Lançamento de efluentes industriais
B22: 12 | C22: Se houver impacto efluente industrial, os requisitos da legislação são atendidos? If there is impact on waste water, are requirements of the guidance met? | D22: Revise a potencial descarte do o esgoto sanitário. Atualizar inventário de descarte de efluentes da unidade. Atualizar a lista de pontos de medição dos efluentes e frequência de amostragem. Essa mudança requer tratamento de efluentes? O procedimento é atualizado? Se necessário, as plantas hidrosanitárias estão revisadas e atualizadas? Os órgãos reguladores precisam ser notificados sobre essa mudança de efluentes (se sim, verifique todos os requisitos da planilha de "Compliance")?
B23: 13 | C23: Se a mudança envolver algum impacto nas calhas de contençõe e/ou ralos do piso, os requisitos da orientação são atendidos? If the change involve any impact to floor drains, are requirements of the guidance met? | D23: Verifique a possibilidade do efluente ou água residuais do processo entrem nas calhas e/ou ralo do piso. Se aplicável, vede ou proteja as calhas e/ou ralo do piso
B24: 14 | C24: Se houver alguma alteração no equipamento existente ou adição de um novo equipamento na estação de tratamento de efluentes, os requisitos da legislação são atendidos? If there is any change to existing or the addition of new wastewater treatment (WWT) equipment, are requirements of the guidance met? | D24: Obter documentação de projeto para o equipamento WWT. Adicione o equipamento WWT ao programa de manutenção preventiva ou inspeção. Avalie o equipamento de controle para determinar a necessidade de peças sobressalentes críticas, desenvolva uma lista dessas peças e tenha peças sobressalentes críticas prontamente disponíveis. Atualize os desenhos de esgoto e tubulação do local. Desenvolva procedimentos operacionais que incluam quem deve ser notificado em caso de transtornos ou mau funcionamento. Treinar operadores.
B25: 15 | C25: Se houver impacto em águas pluviais, os requisitos da legislação são atendidos? If there is impact on storm water, are requirements of the guidance met? | D25: Revisar o impacto potencial para o programa de prevenção da poluição de águas pluviais e condicionamentes da licença.
D27: Total | E27: =COUNTA(E4:E25) -> 0 | F27: =COUNTA(F4:F25) -> 0 | G27: =COUNTA(G4:G25) -> 0 | H27: =SUM(E27:G27) -> 0
D28: Total | E28: =IFERROR(E27/$H$27,"-") -> - | F28: =IFERROR(F27/$H$27,"-") -> - | G28: =IFERROR(G27/$H$27,"-") -> -

Sheet Equipament
B2: Checklist Segurança do Equipamento
B3: Referência (Nº) | C3: Pergunta | D3: Orientação | E3: S | F3: N | G3: N/A | H3: Observação (as ações devem ser registradas apenas no Plano de Ação)
B4: Dispositivo de Proteção para proteger os trabalhadores contra danos
B5: 1 | C5: Existe algum dispositivo de proteção aprovado e eficaz? Is approved and effective equipment guarding in place? | D5: O equipamento deve ter a marcação CE ou certificação UL. Caso contrário, uma Avaliação Pré-Risco deve ser realizada e qualquer isenção deve ser aprovada de acordo com a Política de Equipamentos de Segurança da Essilor
B6: 2 | C6: Os riscos relacionados a adornos, cabelos soltos e roupas largas estão claramente sinalizados? Are identified pinch points clearing labeled? | D6: Coloque e mantenha as sinalizações de advertência próximo aos pontos onde é possível que o funcionário se prenda com adornos, cabelos soltos ou roupas largas.
B7: 3 | C7: Existe um número adequado de paradas de emergência disponíveis e elas foram testadas? Is there an adequate number of E-Stops available and have they been tested? | D7: Paradas de emergência = botão de desligamento de emergência nas máquinas.
B8: 4 | C8: Os testes regulares das paradas de emergência são incorporados ao programa de manutenção preventiva do equipamento e ao checklist de verificação de inspeção pré-uso? Are regular testing of the E-Stops incorporated into the equipment Preventive Maintenance program and on the Pre-Use inspection checklist?
B9: 5 | C9: Os tipos apropriados de intertravamentos estão instalados neste equipamento (por exemplo, à prova de falhas, falhas passivas, falhas ativas, barreiras de luz, botões de comando de duas mãos...? Are appropriate types of interlocks installed on this piece of equipment (e.g., fail-safe, fail-passive, fail-active, light barrier, double-hand command buttons...?
B10: 6 | C10: O teste dos intertravamentos está incorporado no programa de Manutenção Preventiva e no checklist lista de verificação de inspeção pré-uso? Are testing of the interlocks incorporated into Preventive Maintenance program and on the Pre-Use inspection checklist?
B11: 7 | C11: Existe espaço adequado em torno dos painéis de serviço de equipamentos e utilidades para que possam ser acessados? Is there adequate clearance around the equipment & utility service panels so they can be accessed?
B12: Prevenção e Proteção contra incêndio e explosão
B13: 8 | C13: Se os sistemas de prevenção e proteção contra incêndio e explosão forem afetados pela alteração, verifique se os requisitos da planilha "Emergency-Fire" foram verificados? If fire and explosion prevention and protection systems affected by the change, check that the requirement of the "Emergency-Fire" spreadsheet are verified? | D13: Verifique se a alteração afeta qualquer um dos seguintes itens: extintores de incêndio, sistemas de sprinklers automáticos, sistemas fixos de supressão de incêndio, sistema de detecção de incêndio, sistema de alarme de emergência, sinalização e iluminação de emergência, saída e caminho de emergência, lava-olhos/chuveiro de emergência... Em caso afirmativo, preencha a planilha "Emergency Preparedness - Fire Prevention & Protection".
B14: 9 | C14: Se o equipamento novo ou modificado ou o local afetado exigir uma classificação específica de incêndio ou explosão, as atualizações são implementadas? If the new or modified equipment or affected location required a specific fire or explosion rating, are updates implemented?
B15: 10 | C15: A determinação da classificação de incêndio e explosão aplicável foi documentada? Has the determination for the applicable fire and explosion rating been documented?
